Workbook
Name Slicer_Gender_Category: #N/A
Name Slicer_Product_Line: #N/A
Name Slicer_Region: #N/A
Name Slicer_Sales_Channel: #N/A

Sheet Nike_Sales_Uncleaned
A1: Order_ID | B1: Gender_Category | C1: Product_Line | D1: Product_Name | E1: Size | F1: Units_Sold | G1: MRP | H1: Discount_Applied | I1: Revenue | J1: Order_Date | K1: Sales_Channel | L1: Region | M1: Profit
A2: 2016 | B2: Women | C2: Basketball | D2: Air Jordan | E2: M | F2: 1 | G2: 9871.75 | H2: 0.3 | I2: 6910.22 | K2: Retail | L2: Hyderabad | M2: 2452.69
A3: 2031 | B3: Men | C3: Soccer | D3: Premier Iii | F3: 4 | G3: 3493.04 | H3: 0.82 | I3: 2514.99 | J3: 45421 | K3: Online | L3: Delhi | M3: 350.7
A4: 2063 | B4: Women | C4: Basketball | D4: Air Jordan | E4: M | F4: 1 | G4: 9751 | H4: 0.16 | I4: 8190.84 | J4: 45541 | K4: Retail | L4: Pune | M4: 1130.31
A5: 2071 | B5: Kids | C5: Lifestyle | D5: Blazer Mid | E5: M | F5: 3 | G5: 7849.81 | H5: 0.49 | I5: 12010.21 | J5: 45669 | K5: Retail | L5: Pune | M5: -882.96
A6: 2089 | B6: Women | C6: Training | D6: Flex Trainer | E6: L | F6: 2 | G6: 6874.77 | H6: 0.6 | I6: 5499.82 | J6: 45628 | K6: Online | L6: Mumbai | M6: -1076.66
A7: 2114 | B7: Women | C7: Training | D7: Flex Trainer | E7: Xl | F7: 1 | G7: 3167.33 | H7: 0.53 | I7: 1488.65 | K7: Retail | L7: Pune | M7: 1567.37
A8: 2135 | B8: Men | C8: Basketball | D8: Zoom Freak | E8: L | F8: 2 | G8: 9106.61 | H8: 0.74 | I8: 4735.44 | J8: 45599 | K8: Retail | L8: Hyderabad | M8: 2422.38
A9: 2150 | B9: Women | C9: Basketball | D9: Lebron 20 | E9: M | F9: 2 | G9: 3313.21 | H9: 0.48 | I9: 3445.74 | J9: 45844 | K9: Online | L9: Bengaluru | M9: 3221.62
A10: 2169 | B10: Kids | C10: Training | D10: Flex Trainer | F10: 4 | G10: 4046.05 | H10: 0.01 | I10: 16022.36 | J10: 45640 | K10: Retail | L10: Delhi | M10: 1057.58
A11: 2185 | B11: Women | C11: Training | D11: Zoomx Invincible | E11: Xl | F11: 4 | G11: 4207.44 | H11: 0.59 | I11: 6900.2 | J11: 45816 | K11: Online | L11: Kolkata | M11: -615.48
A12: 2202 | B12: Men | C12: Basketball | D12: Kyrie Flytrap | E12: M | F12: -1 | G12: 7918.93 | H12: 1.06 | I12: 475.14 | J12: 45842 | K12: Retail | L12: Bengaluru | M12: 1994.42
A13: 2222 | B13: Men | C13: Training | D13: Zoomx Invincible | E13: Xl | F13: 2 | G13: 8897.19 | H13: 0.11 | I13: 15837 | J13: 45647 | K13: Retail | L13: Mumbai | M13: 2821.69
A14: 2248 | B14: Men | C14: Training | D14: Metcon 7 | E14: M | F14: 4 | G14: 8249.96 | H14: 0.24 | I14: 25079.88 | J14: 45307 | K14: Online | L14: Bengaluru | M14: 1625.14
A15: 2300 | B15: Men | C15: Basketball | D15: Air Jordan | E15: L | F15: 3 | G15: 6331.64 | H15: 0.78 | I15: 4178.88 | J15: 45521 | K15: Retail | L15: Delhi | M15: 3380.28
A16: 2306 | B16: Kids | C16: Basketball | D16: Air Jordan | F16: 1 | G16: 8267.56 | H16: 0.29 | I16: 5869.97 | J16: 45606 | K16: Retail | L16: Bengaluru | M16: 476.25
A17: 2328 | B17: Men | C17: Lifestyle | D17: Waffle One | E17: 6 | F17: 2 | G17: 6449.46 | H17: 0.29 | I17: 9158.23 | J17: 45605 | K17: Online | L17: Mumbai | M17: 39.69
A18: 2367 | B18: Kids | C18: Lifestyle | D18: Dunk Low | E18: Xl | F18: 4 | G18: 6202.99 | H18: 0.84 | I18: 3969.91 | J18: 45608 | K18: Online | L18: Bengaluru | M18: -202.12
A19: 2412 | B19: Kids | C19: Lifestyle | D19: Blazer Mid | E19: Xl | F19: 1 | G19: 4920.3 | H19: 0.14 | I19: 4231.46 | K19: Retail | L19: Mumbai | M19: 1135.72
A20: 2413 | B20: Men | C20: Training | D20: Flex Trainer | E20: Xl | F20: 3 | G20: 7005.67 | H20: 0.15 | I20: 17864.46 | K20: Retail | L20: Kolkata | M20: 2329.98
A21: 2432 | B21: Women | C21: Basketball | D21: Zoom Freak | E21: L | F21: 1 | G21: 3036.61 | H21: 0.86 | I21: 425.13 | J21: 45591 | K21: Online | L21: Mumbai | M21: 3754.3
A22: 2460 | B22: Women | C22: Basketball | D22: Zoom Freak | E22: Xl | F22: 2 | G22: 5482.96 | H22: 0.35 | I22: 7127.85 | J22: 45600 | K22: Online | L22: Kolkata | M22: -823.8
A23: 2481 | B23: Women | C23: Soccer | D23: Premier Iii | E23: 7 | F23: 1 | G23: 9145.37 | H23: 0.07 | I23: 8505.19 | J23: 45764 | K23: Online | L23: Pune | M23: 1755.19
A24: 2487 | B24: Men | C24: Running | D24: Air Zoom | E24: L | F24: 3 | G24: 5881.13 | H24: 0.8 | I24: 3528.68 | J24: 45747 | K24: Online | L24: Hyderabad | M24: 2108.4
A25: 2490 | B25: Women | C25: Soccer | D25: Premier Iii | E25: L | F25: 3 | G25: 5015.19 | H25: 0.75 | I25: 3761.39 | J25: 45622 | K25: Online | L25: Hyderabad | M25: -494.53
A26: 2496 | B26: Kids | C26: Running | D26: React Infinity | E26: M | F26: 2 | G26: 4110.72 | H26: 0.32 | I26: 5590.58 | J26: 45650 | K26: Retail | L26: Bengaluru | M26: 3894.95
A27: 2535 | B27: Men | C27: Soccer | D27: Tiempo Legend | E27: Xl | F27: 2 | G27: 2786.84 | H27: 0.21 | I27: 4403.21 | J27: 45682 | K27: Online | L27: Mumbai | M27: 3345.36
A28: 2550 | B28: Men | C28: Soccer | D28: Premier Iii | E28: Xl | F28: 1 | G28: 6121.21 | H28: 0.05 | I28: 5815.15 | J28: 45177 | K28: Online | L28: Kolkata | M28: 2470.08
A29: 2563 | B29: Men | C29: Soccer | D29: Mercurial Superfly | E29: M | F29: 2 | G29: 9443.35 | H29: 0.54 | I29: 8687.88 | J29: 45760 | K29: Retail | L29: Kolkata | M29: 2706.61
A30: 2569 | B30: Women | C30: Basketball | D30: Air Jordan | E30: L | F30: 2 | G30: 9605.11 | H30: 0.88 | I30: 2305.23 | J30: 45528 | K30: Online | L30: Hyderabad | M30: 128.89
A31: 2594 | B31: Women | C31: Training | D31: Zoomx Invincible | E31: Xl | F31: 3 | G31: 7944.34 | H31: 0.67 | I31: 7864.9 | J31: 45345 | K31: Retail | L31: Hyderabad | M31: 1534.91
A32: 2613 | B32: Women | C32: Lifestyle | D32: Waffle One | E32: 7 | F32: 3 | G32: 4374.83 | H32: 0.27 | I32: 9580.88 | K32: Retail | L32: Delhi | M32: 1473.37
A33: 2615 | B33: Women | C33: Soccer | D33: Phantom Gt | E33: Xl | F33: 3 | G33: 3042.37 | H33: 0.12 | I33: 8031.86 | J33: 45740 | K33: Online | L33: Pune | M33: 2105.48
A34: 2621 | B34: Kids | C34: Soccer | D34: Phantom Gt | E34: L | F34: 3 | G34: 6466.57 | H34: 0.59 | I34: 7953.88 | J34: 45431 | K34: Online | L34: Bengaluru | M34: -1152.86
A35: 2709 | B35: Kids | C35: Running | D35: Free Rn | E35: 10 | F35: 1 | G35: 6302.98 | H35: 0.48 | I35: 3277.55 | J35: 45724 | K35: Retail | L35: Delhi | M35: 2835.93
A36: 2713 | B36: Men | C36: Lifestyle | D36: Air Force 1 | E36: L | F36: 1 | G36: 7877.36 | H36: 0.55 | I36: 3544.81 | J36: 45787 | K36: Retail | L36: Kolkata | M36: 3663.49
A37: 2780 | B37: Men | C37: Training | D37: Metcon 7 | E37: 6 | F37: 1 | G37: 4308.75 | H37: 0.32 | I37: 2929.95 | K37: Online | L37: Hyderabad | M37: 799.35
A38: 2781 | B38: Men | C38: Training | D38: Metcon 7 | E38: 12 | F38: 1 | G38: 6546.59 | H38: 0.68 | I38: 2094.91 | J38: 45172 | K38: Retail | L38: Bengaluru | M38: 1504.31
A39: 2799 | B39: Kids | C39: Training | D39: Superrep Go | F39: 3 | G39: 2359.47 | H39: 0.54 | I39: 3256.07 | J39: 45846 | K39: Online | L39: Mumbai | M39: 3165.65
A40: 2810 | B40: Men | C40: Running | D40: Air Zoom | E40: 7 | F40: 2 | G40: 2943.44 | H40: 0.53 | I40: 2766.83 | K40: Retail | L40: Hyderabad | M40: 405.67
...

Sheet Sheet2
A9: Sum of Revenue | B9: Column Labels | I9: Row Labels | J9: Sum of Revenue
A10: Row Labels | B10: Basketball | C10: Lifestyle | D10: Running | E10: Soccer | F10: Training | G10: Grand Total | I10: Air Force 1 | J10: 42612.14 | L10: Row Labels | M10: Sum of Revenue
A11: Kids | B11: 14140.52 | C11: 71713.02 | D11: 69973.5 | E11: 17214.56 | F11: 54045.39 | G11: 227086.99 | I11: Air Jordan | J11: 44854.03 | L11: Bengaluru | M11: 127441.95
A12: Online | B12: 4530.7 | C12: 29789.2 | D12: 52307.4 | E12: 7953.88 | F12: 21261.97 | G12: 115843.15 | I12: Air Zoom | J12: 58144.3 | L12: Delhi | M12: 123952.47
A13: Retail | B13: 9609.82 | C13: 41923.82 | D13: 17666.1 | E13: 9260.68 | F13: 32783.42 | G13: 111243.84 | I13: Blazer Mid | J13: 50239.43 | L13: Hyderabad | M13: 140181.79
A14: Men | B14: 79580.5 | C14: 61655.68 | D14: 18379.15 | E14: 59901.91 | F14: 91137.17 | G14: 310654.41 | I14: Flex Trainer | J14: 77067.95 | L14: Kolkata | M14: 165502.6
A15: Online | B15: 32352.89 | C15: 35263.6 | D15: 12681.49 | E15: 31025.2 | F15: 30691.74 | G15: 142014.92 | I15: Lebron 20 | J15: 63676.17 | L15: Mumbai | M15: 106244.5
A16: Retail | B16: 47227.61 | C16: 26392.08 | D16: 5697.66 | E16: 28876.71 | F16: 60445.43 | G16: 168639.49 | I16: Phantom Gt | J16: 42580.61 | L16: Pune | M16: 123655.54
A17: Women | B17: 75732.56 | C17: 32040.76 | D17: 6257.1 | E17: 69160.3 | F17: 66046.73 | G17: 249237.45 | I17: Superrep Go | J17: 49055.58 | L17: Grand Total | M17: 786978.85
A18: Online | B18: 60631.5 | E18: 46541.68 | F18: 35086.33 | G18: 142259.51 | I18: Zoom Freak | J18: 51500.51
A19: Retail | B19: 15101.06 | C19: 32040.76 | D19: 6257.1 | E19: 22618.62 | F19: 30960.4 | G19: 106977.94 | I19: Zoomx Invincible | J19: 46404.46
A20: Grand Total | B20: 169453.58 | C20: 165409.46 | D20: 94609.75 | E20: 146276.77 | F20: 211229.29 | G20: 786978.85 | I20: Grand Total | J20: 526135.18

Sheet Sheet3
D3: Product_name | E3: =Sheet2!J9 -> Sum of Revenue
D4: =Sheet2!I10 -> Air Force 1 | E4: =Sheet2!J10 -> 42612.14
D5: =Sheet2!I11 -> Air Jordan | E5: =Sheet2!J11 -> 44854.03
D6: =Sheet2!I12 -> Air Zoom | E6: =Sheet2!J12 -> 58144.3
D7: =Sheet2!I13 -> Blazer Mid | E7: =Sheet2!J13 -> 50239.43
D8: =Sheet2!I14 -> Flex Trainer | E8: =Sheet2!J14 -> 77067.95
D9: =Sheet2!I15 -> Lebron 20 | E9: =Sheet2!J15 -> 63676.17
D10: =Sheet2!I16 -> Phantom Gt | E10: =Sheet2!J16 -> 42580.61
D11: =Sheet2!I17 -> Superrep Go | E11: =Sheet2!J17 -> 49055.58
D12: =Sheet2!I18 -> Zoom Freak | E12: =Sheet2!J18 -> 51500.51
D13: =Sheet2!I19 -> Zoomx Invincible | E13: =Sheet2!J19 -> 46404.46
D14: =Sheet2!I20 -> Grand Total | E14: =Sheet2!J20 -> 526135.18
